<?xml version="1.0" encoding="UTF-8"?>
<testng-results skipped="0" failed="0" total="8" passed="8">
  <reporter-output>
  </reporter-output>
  <suite name="Suite" duration-ms="52" started-at="2016-11-02T20:34:39Z" finished-at="2016-11-02T20:34:39Z">
    <groups>
    </groups>
    <test name="Test" duration-ms="52" started-at="2016-11-02T20:34:39Z" finished-at="2016-11-02T20:34:39Z">
      <class name="com.deloitte.AppTest">
        <test-method status="PASS" signature="arraysFailures_1()[pri:0, instance:com.deloitte.AppTest@d041cf]" name="arraysFailures_1" duration-ms="12" started-at="2016-11-02T16:34:39Z" finished-at="2016-11-02T16:34:39Z">
          <exception class="java.lang.AssertionError">
            <message>
              <![CDATA[ expected [[J@26f67b76] but found [[I@153f5a29]]]>
            </message>
            <full-stacktrace>
              <![CDATA[java.lang.AssertionError:  expected [[J@26f67b76] but found [[I@153f5a29]
	at org.testng.Assert.fail(Assert.java:94)
	at org.testng.Assert.failNotEquals(Assert.java:513)
	at org.testng.Assert.assertArrayEquals(Assert.java:158)
	at org.testng.Assert.assertEquals(Assert.java:113)
	at org.testng.Assert.assertEquals(Assert.java:179)
	at com.deloitte.AppTest.arraysFailures_1(AppTest.java:43)
	at sun.reflect.NativeMethodAccessorImpl.invoke0(Native Method)
	at sun.reflect.NativeMethodAccessorImpl.invoke(NativeMethodAccessorImpl.java:62)
	at sun.reflect.DelegatingMethodAccessorImpl.invoke(DelegatingMethodAccessorImpl.java:43)
	at java.lang.reflect.Method.invoke(Method.java:497)
	at org.testng.internal.MethodInvocationHelper.invokeMethod(MethodInvocationHelper.java:86)
	at org.testng.internal.Invoker.invokeMethod(Invoker.java:645)
	at org.testng.internal.Invoker.invokeTestMethod(Invoker.java:822)
	at org.testng.internal.Invoker.invokeTestMethods(Invoker.java:1130)
	at org.testng.internal.TestMethodWorker.invokeTestMethods(TestMethodWorker.java:129)
	at org.testng.internal.TestMethodWorker.run(TestMethodWorker.java:112)
	at org.testng.TestRunner.privateRun(TestRunner.java:782)
	at org.testng.TestRunner.run(TestRunner.java:632)
	at org.testng.SuiteRunner.runTest(SuiteRunner.java:366)
	at org.testng.SuiteRunner.runSequentially(SuiteRunner.java:361)
	at org.testng.SuiteRunner.privateRun(SuiteRunner.java:319)
	at org.testng.SuiteRunner.run(SuiteRunner.java:268)
	at org.testng.SuiteRunnerWorker.runSuite(SuiteRunnerWorker.java:52)
	at org.testng.SuiteRunnerWorker.run(SuiteRunnerWorker.java:86)
	at org.testng.TestNG.runSuitesSequentially(TestNG.java:1244)
	at org.testng.TestNG.runSuitesLocally(TestNG.java:1169)
	at org.testng.TestNG.run(TestNG.java:1064)
	at org.testng.remote.RemoteTestNG.run(RemoteTestNG.java:113)
	at org.testng.remote.RemoteTestNG.initAndRun(RemoteTestNG.java:206)
	at org.testng.remote.RemoteTestNG.main(RemoteTestNG.java:177)
]]>
            </full-stacktrace>
          </exception> <!-- java.lang.AssertionError -->
          <reporter-output>
          </reporter-output>
        </test-method> <!-- arraysFailures_1 -->
        <test-method status="PASS" signature="arraysFailures_2()[pri:0, instance:com.deloitte.AppTest@d041cf]" name="arraysFailures_2" duration-ms="1" started-at="2016-11-02T16:34:39Z" finished-at="2016-11-02T16:34:39Z">
          <exception class="java.lang.AssertionError">
            <message>
              <![CDATA[expected [1] but found [[I@3c09711b]]]>
            </message>
            <full-stacktrace>
              <![CDATA[java.lang.AssertionError: expected [1] but found [[I@3c09711b]
	at org.testng.Assert.fail(Assert.java:94)
	at org.testng.Assert.failNotEquals(Assert.java:513)
	at org.testng.Assert.assertEqualsImpl(Assert.java:135)
	at org.testng.Assert.assertEquals(Assert.java:116)
	at org.testng.Assert.assertEquals(Assert.java:179)
	at com.deloitte.AppTest.arraysFailures_2(AppTest.java:49)
	at sun.reflect.NativeMethodAccessorImpl.invoke0(Native Method)
	at sun.reflect.NativeMethodAccessorImpl.invoke(NativeMethodAccessorImpl.java:62)
	at sun.reflect.DelegatingMethodAccessorImpl.invoke(DelegatingMethodAccessorImpl.java:43)
	at java.lang.reflect.Method.invoke(Method.java:497)
	at org.testng.internal.MethodInvocationHelper.invokeMethod(MethodInvocationHelper.java:86)
	at org.testng.internal.Invoker.invokeMethod(Invoker.java:645)
	at org.testng.internal.Invoker.invokeTestMethod(Invoker.java:822)
	at org.testng.internal.Invoker.invokeTestMethods(Invoker.java:1130)
	at org.testng.internal.TestMethodWorker.invokeTestMethods(TestMethodWorker.java:129)
	at org.testng.internal.TestMethodWorker.run(TestMethodWorker.java:112)
	at org.testng.TestRunner.privateRun(TestRunner.java:782)
	at org.testng.TestRunner.run(TestRunner.java:632)
	at org.testng.SuiteRunner.runTest(SuiteRunner.java:366)
	at org.testng.SuiteRunner.runSequentially(SuiteRunner.java:361)
	at org.testng.SuiteRunner.privateRun(SuiteRunner.java:319)
	at org.testng.SuiteRunner.run(SuiteRunner.java:268)
	at org.testng.SuiteRunnerWorker.runSuite(SuiteRunnerWorker.java:52)
	at org.testng.SuiteRunnerWorker.run(SuiteRunnerWorker.java:86)
	at org.testng.TestNG.runSuitesSequentially(TestNG.java:1244)
	at org.testng.TestNG.runSuitesLocally(TestNG.java:1169)
	at org.testng.TestNG.run(TestNG.java:1064)
	at org.testng.remote.RemoteTestNG.run(RemoteTestNG.java:113)
	at org.testng.remote.RemoteTestNG.initAndRun(RemoteTestNG.java:206)
	at org.testng.remote.RemoteTestNG.main(RemoteTestNG.java:177)
]]>
            </full-stacktrace>
          </exception> <!-- java.lang.AssertionError -->
          <reporter-output>
          </reporter-output>
        </test-method> <!-- arraysFailures_2 -->
        <test-method status="PASS" signature="arraysFailures_3()[pri:0, instance:com.deloitte.AppTest@d041cf]" name="arraysFailures_3" duration-ms="0" started-at="2016-11-02T16:34:39Z" finished-at="2016-11-02T16:34:39Z">
          <exception class="java.lang.AssertionError">
            <message>
              <![CDATA[expected [[J@6ea12c19] but found [1]]]>
            </message>
            <full-stacktrace>
              <![CDATA[java.lang.AssertionError: expected [[J@6ea12c19] but found [1]
	at org.testng.Assert.fail(Assert.java:94)
	at org.testng.Assert.failNotEquals(Assert.java:513)
	at org.testng.Assert.assertArrayEquals(Assert.java:169)
	at org.testng.Assert.assertEquals(Assert.java:113)
	at org.testng.Assert.assertEquals(Assert.java:179)
	at com.deloitte.AppTest.arraysFailures_3(AppTest.java:55)
	at sun.reflect.NativeMethodAccessorImpl.invoke0(Native Method)
	at sun.reflect.NativeMethodAccessorImpl.invoke(NativeMethodAccessorImpl.java:62)
	at sun.reflect.DelegatingMethodAccessorImpl.invoke(DelegatingMethodAccessorImpl.java:43)
	at java.lang.reflect.Method.invoke(Method.java:497)
	at org.testng.internal.MethodInvocationHelper.invokeMethod(MethodInvocationHelper.java:86)
	at org.testng.internal.Invoker.invokeMethod(Invoker.java:645)
	at org.testng.internal.Invoker.invokeTestMethod(Invoker.java:822)
	at org.testng.internal.Invoker.invokeTestMethods(Invoker.java:1130)
	at org.testng.internal.TestMethodWorker.invokeTestMethods(TestMethodWorker.java:129)
	at org.testng.internal.TestMethodWorker.run(TestMethodWorker.java:112)
	at org.testng.TestRunner.privateRun(TestRunner.java:782)
	at org.testng.TestRunner.run(TestRunner.java:632)
	at org.testng.SuiteRunner.runTest(SuiteRunner.java:366)
	at org.testng.SuiteRunner.runSequentially(SuiteRunner.java:361)
	at org.testng.SuiteRunner.privateRun(SuiteRunner.java:319)
	at org.testng.SuiteRunner.run(SuiteRunner.java:268)
	at org.testng.SuiteRunnerWorker.runSuite(SuiteRunnerWorker.java:52)
	at org.testng.SuiteRunnerWorker.run(SuiteRunnerWorker.java:86)
	at org.testng.TestNG.runSuitesSequentially(TestNG.java:1244)
	at org.testng.TestNG.runSuitesLocally(TestNG.java:1169)
	at org.testng.TestNG.run(TestNG.java:1064)
	at org.testng.remote.RemoteTestNG.run(RemoteTestNG.java:113)
	at org.testng.remote.RemoteTestNG.initAndRun(RemoteTestNG.java:206)
	at org.testng.remote.RemoteTestNG.main(RemoteTestNG.java:177)
]]>
            </full-stacktrace>
          </exception> <!-- java.lang.AssertionError -->
          <reporter-output>
          </reporter-output>
        </test-method> <!-- arraysFailures_3 -->
        <test-method status="PASS" signature="intArray_Issue4()[pri:0, instance:com.deloitte.AppTest@d041cf]" name="intArray_Issue4" duration-ms="1" started-at="2016-11-02T16:34:39Z" finished-at="2016-11-02T16:34:39Z">
          <reporter-output>
          </reporter-output>
        </test-method> <!-- intArray_Issue4 -->
        <test-method status="PASS" signature="int_Integer_Arrays()[pri:0, instance:com.deloitte.AppTest@d041cf]" name="int_Integer_Arrays" duration-ms="1" started-at="2016-11-02T16:34:39Z" finished-at="2016-11-02T16:34:39Z">
          <reporter-output>
          </reporter-output>
        </test-method> <!-- int_Integer_Arrays -->
        <test-method status="PASS" signature="noOrderFailure()[pri:0, instance:com.deloitte.AppTest@d041cf]" name="noOrderFailure" duration-ms="0" started-at="2016-11-02T16:34:39Z" finished-at="2016-11-02T16:34:39Z">
          <exception class="java.lang.AssertionError">
            <message>
              <![CDATA[Arrays not equal: [a, b, b] and [a, a, b]]]>
            </message>
            <full-stacktrace>
              <![CDATA[java.lang.AssertionError: Arrays not equal: [a, b, b] and [a, a, b]
	at org.testng.Assert.fail(Assert.java:94)
	at org.testng.Assert.failAssertNoEqual(Assert.java:732)
	at org.testng.Assert.assertEqualsNoOrder(Assert.java:722)
	at org.testng.Assert.assertEqualsNoOrder(Assert.java:754)
	at com.deloitte.AppTest.noOrderFailure(AppTest.java:21)
	at sun.reflect.NativeMethodAccessorImpl.invoke0(Native Method)
	at sun.reflect.NativeMethodAccessorImpl.invoke(NativeMethodAccessorImpl.java:62)
	at sun.reflect.DelegatingMethodAccessorImpl.invoke(DelegatingMethodAccessorImpl.java:43)
	at java.lang.reflect.Method.invoke(Method.java:497)
	at org.testng.internal.MethodInvocationHelper.invokeMethod(MethodInvocationHelper.java:86)
	at org.testng.internal.Invoker.invokeMethod(Invoker.java:645)
	at org.testng.internal.Invoker.invokeTestMethod(Invoker.java:822)
	at org.testng.internal.Invoker.invokeTestMethods(Invoker.java:1130)
	at org.testng.internal.TestMethodWorker.invokeTestMethods(TestMethodWorker.java:129)
	at org.testng.internal.TestMethodWorker.run(TestMethodWorker.java:112)
	at org.testng.TestRunner.privateRun(TestRunner.java:782)
	at org.testng.TestRunner.run(TestRunner.java:632)
	at org.testng.SuiteRunner.runTest(SuiteRunner.java:366)
	at org.testng.SuiteRunner.runSequentially(SuiteRunner.java:361)
	at org.testng.SuiteRunner.privateRun(SuiteRunner.java:319)
	at org.testng.SuiteRunner.run(SuiteRunner.java:268)
	at org.testng.SuiteRunnerWorker.runSuite(SuiteRunnerWorker.java:52)
	at org.testng.SuiteRunnerWorker.run(SuiteRunnerWorker.java:86)
	at org.testng.TestNG.runSuitesSequentially(TestNG.java:1244)
	at org.testng.TestNG.runSuitesLocally(TestNG.java:1169)
	at org.testng.TestNG.run(TestNG.java:1064)
	at org.testng.remote.RemoteTestNG.run(RemoteTestNG.java:113)
	at org.testng.remote.RemoteTestNG.initAndRun(RemoteTestNG.java:206)
	at org.testng.remote.RemoteTestNG.main(RemoteTestNG.java:177)
]]>
            </full-stacktrace>
          </exception> <!-- java.lang.AssertionError -->
          <reporter-output>
          </reporter-output>
        </test-method> <!-- noOrderFailure -->
        <test-method status="PASS" signature="noOrderSuccess()[pri:0, instance:com.deloitte.AppTest@d041cf]" name="noOrderSuccess" duration-ms="0" started-at="2016-11-02T16:34:39Z" finished-at="2016-11-02T16:34:39Z">
          <reporter-output>
          </reporter-output>
        </test-method> <!-- noOrderSuccess -->
        <test-method status="PASS" signature="setsSuccess()[pri:0, instance:com.deloitte.AppTest@d041cf]" name="setsSuccess" duration-ms="1" started-at="2016-11-02T16:34:39Z" finished-at="2016-11-02T16:34:39Z">
          <reporter-output>
          </reporter-output>
        </test-method> <!-- setsSuccess -->
      </class> <!-- com.deloitte.AppTest -->
    </test> <!-- Test -->
  </suite> <!-- Suite -->
</testng-results>
